Workbook
Name Slicer_Agent_Assigned: #N/A
Name Slicer_Answered: #N/A
Name Slicer_Breached_SLA: #N/A
Name Slicer_Breached_SLA1: #N/A
Name Slicer_Current_Status: #N/A
Name Slicer_Department: #N/A
Name Slicer_Overdue: #N/A
Name Slicer_Priority: #N/A
Name Slicer_Source: #N/A
Name Slicer_Team_Assigned: #N/A
Name Slicer_Type: #N/A

Sheet helpdesk_tickets
A1: Ticket Number | B1: Date Created | C1: Subject | D1: From | E1: From Email | F1: Priority | G1: Department | H1: Type | I1: Source | J1: Current Status | K1: Last Updated | L1: Due Date | M1: Overdue | N1: Answered | O1: Agent Assigned | P1: Team Lead | Q1: Team Assigned | R1: Thread Count | S1: Attachment Count | T1: Category | U1: Issue Origin | V1: Select Ticket Status Update | W1: SLA Due Date | X1: Breached SLA | Y1: SR No. | Z1: Corrective Actions | AA1: Preventive Actions | AB1: Closed By
A2: 111636 | B2: 44267.415 | C2: Error Displaying In Different Module | D2: Jasper John | E2: jasper.john@gmail.com | F2: Emergency | G2: SAP JDE Support Department | H2: Incident / Problem | I2: Web | J2: Closed | K2: 44279.722 | L2: 44267.581 | M2: 0 | N2: 1 | O2: Jared Smith | P2: N/A | Q2: SAP Support Team | R2: 16 | S2: 2 | T2: PROD | U2: PRODUCTION | V2: New Ticket | W2: {=IF(H2="Request","No SLA for Request", IF(F2="Emergency",B2+(4/24), WORKDAY(B2, _xlfn.IFS(F2="High", 3, F2="Normal", 5, F2="Low", 10))))} -> 44267.581 | X2: =IF(K2>=W2,"Yes",IF(W2="No SLA for Request","N/A","No")) -> Yes
A3: 111632 | B3: 44265.681 | C3: Approval Workflow Error | D3: Erick White | E3: ewhite@yahoo.com | F3: Emergency | G3: SAP JDE Support Department | H3: Incident / Problem | I3: Web | J3: Resolved | K3: 44273.719 | L3: 44270.681 | M3: 1 | N3: 1 | O3: Mark Jikkins | P3: N/A | Q3: JDE Support Team | R3: 28 | S3: 6 | T3: PROD | U3: PRODUCTION | V3: New Ticket | W3: {=IF(H3="Request","No SLA for Request", IF(F3="Emergency",B3+(4/24), WORKDAY(B3, _xlfn.IFS(F3="High", 3, F3="Normal", 5, F3="Low", 10))))} -> 44265.848 | X3: =IF(K3>=W3,"Yes",IF(W3="No SLA for Request","N/A","No")) -> Yes
A4: 111621 | B4: 44249.506 | C4: Public Ip Trusted Certificate Authority Error | D4: Tomi Yamamoto | E4: tyamamoto@gmail.com | F4: Emergency | G4: InterN/Al Technical Department | H4: Incident / Problem | I4: Web | J4: Closed | K4: 44260.611 | L4: 44250.006 | M4: 0 | N4: 1 | O4: Jared Smith | P4: N/A | Q4: Network Team | R4: 5 | S4: 1 | T4: PROD | U4: PRODUCTION | V4: New Ticket | W4: {=IF(H4="Request","No SLA for Request", IF(F4="Emergency",B4+(4/24), WORKDAY(B4, _xlfn.IFS(F4="High", 3, F4="Normal", 5, F4="Low", 10))))} -> 44249.672 | X4: =IF(K4>=W4,"Yes",IF(W4="No SLA for Request","N/A","No")) -> Yes
A5: 111608 | B5: 44242.487 | C5: Jde Slowdown | D5: Riza Richardson | E5: rrichardson@mailiN/Ator.com | F5: Emergency | G5: SAP JDE Support Department | H5: Incident / Problem | I5: Web | J5: Closed | K5: 44251.736 | L5: 44242.987 | M5: 0 | N5: 1 | O5: Jared Smith | P5: N/A | Q5: JDE Support Team | R5: 12 | S5: 1 | T5: PROD | U5: PRODUCTION | V5: Close Ticket | W5: {=IF(H5="Request","No SLA for Request", IF(F5="Emergency",B5+(4/24), WORKDAY(B5, _xlfn.IFS(F5="High", 3, F5="Normal", 5, F5="Low", 10))))} -> 44242.653 | X5: =IF(K5>=W5,"Yes",IF(W5="No SLA for Request","N/A","No")) -> Yes
A6: 111596 | B6: 44218.457 | C6: Jde Slow Down | D6: Riza Richardson | E6: rrichardson@mailiN/Ator.com | F6: Emergency | G6: SAP JDE Support Department | H6: Incident / Problem | I6: Web | J6: Closed | K6: 44225.722 | L6: 44218.957 | M6: 0 | N6: 1 | O6: Jared Smith | P6: N/A | Q6: JDE Support Team | R6: 7 | S6: 1 | T6: PROD | U6: PRODUCTION | V6: Close Ticket | W6: {=IF(H6="Request","No SLA for Request", IF(F6="Emergency",B6+(4/24), WORKDAY(B6, _xlfn.IFS(F6="High", 3, F6="Normal", 5, F6="Low", 10))))} -> 44218.624 | X6: =IF(K6>=W6,"Yes",IF(W6="No SLA for Request","N/A","No")) -> Yes
A7: 111491 | B7: 44063.4 | C7: Error 504 Gateway Timeout Again | D7: Aurora Miller | E7: aurora.miller@outlook.com | F7: Emergency | G7: SAP JDE Support Department | H7: Incident / Problem | I7: Web | J7: Closed | K7: 44211.692 | L7: 44063.9 | M7: 0 | N7: 1 | O7: Jared Smith | P7: N/A | Q7: SAP Support Team | R7: 11 | S7: 1 | T7: PROD | U7: PRODUCTION | V7: Close Ticket | W7: {=IF(H7="Request","No SLA for Request", IF(F7="Emergency",B7+(4/24), WORKDAY(B7, _xlfn.IFS(F7="High", 3, F7="Normal", 5, F7="Low", 10))))} -> 44063.567 | X7: =IF(K7>=W7,"Yes",IF(W7="No SLA for Request","N/A","No")) -> Yes
A8: 111571 | B8: 44175.399 | C8: Login Issue | D8: Aurora Miller | E8: aurora.miller@outlook.com | F8: Emergency | G8: SAP JDE Support Department | H8: Incident / Problem | I8: Web | J8: Closed | K8: 44200.742 | L8: 44175.899 | M8: 0 | N8: 1 | O8: Jared Smith | P8: N/A | Q8: SAP Support Team | R8: 5 | S8: 4 | T8: PROD | U8: PRODUCTION | V8: Open | W8: {=IF(H8="Request","No SLA for Request", IF(F8="Emergency",B8+(4/24), WORKDAY(B8, _xlfn.IFS(F8="High", 3, F8="Normal", 5, F8="Low", 10))))} -> 44175.566 | X8: =IF(K8>=W8,"Yes",IF(W8="No SLA for Request","N/A","No")) -> Yes
A9: 111575 | B9: 44175.416 | C9: "Bea.Jolt" Login Error | D9: Aurora Miller | E9: aurora.miller@outlook.com | F9: Emergency | G9: SAP JDE Support Department | H9: Incident / Problem | I9: Web | J9: Closed | K9: 44200.74 | L9: 44175.916 | M9: 0 | N9: 1 | O9: Jared Smith | P9: N/A | Q9: SAP Support Team | R9: 5 | S9: 1 | T9: PROD | U9: PRODUCTION | V9: Open | W9: {=IF(H9="Request","No SLA for Request", IF(F9="Emergency",B9+(4/24), WORKDAY(B9, _xlfn.IFS(F9="High", 3, F9="Normal", 5, F9="Low", 10))))} -> 44175.583 | X9: =IF(K9>=W9,"Yes",IF(W9="No SLA for Request","N/A","No")) -> Yes
A10: 111576 | B10: 44175.419 | C10: Slow Performance | D10: Aurora Miller | E10: aurora.miller@outlook.com | F10: Emergency | G10: SAP JDE Support Department | H10: Incident / Problem | I10: Web | J10: Closed | K10: 44200.739 | L10: 44175.919 | M10: 0 | N10: 1 | O10: Jared Smith | P10: N/A | Q10: SAP Support Team | R10: 5 | S10: 1 | T10: PROD | U10: PRODUCTION | V10: Open | W10: {=IF(H10="Request","No SLA for Request", IF(F10="Emergency",B10+(4/24), WORKDAY(B10, _xlfn.IFS(F10="High", 3, F10="Normal", 5, F10="Low", 10))))} -> 44175.586 | X10: =IF(K10>=W10,"Yes",IF(W10="No SLA for Request","N/A","No")) -> Yes
A11: 111581 | B11: 44183.428 | C11: Hr Technical AN/Alyzer In Test | D11: Kian Rogers | E11: krogers@mailiN/Ator.com | F11: Emergency | G11: SAP JDE Support Department | H11: Request | I11: Web | J11: Closed | K11: 44200.501 | L11: 44183.928 | M11: 0 | N11: 1 | O11: Jared Smith | P11: N/A | Q11: JDE Support Team | R11: 9 | S11: 2 | T11: NON-PROD | U11: TEST | V11: Close Ticket | W11: {=IF(H11="Request","No SLA for Request", IF(F11="Emergency",B11+(4/24), WORKDAY(B11, _xlfn.IFS(F11="High", 3, F11="Normal", 5, F11="Low", 10))))} -> No SLA for Request | X11: =IF(K11>=W11,"Yes",IF(W11="No SLA for Request","N/A","No")) -> N/A
A12: 111586 | B12: 44188.637 | C12: Open Vpn Authenticator App Setup | D12: Kenex Willows | E12: kwillows@yahoo.com | F12: Emergency | G12: SAP JDE Support Department | H12: Request | I12: Web | J12: Closed | K12: 44193.734 | L12: 44189.137 | M12: 0 | N12: 1 | O12: Jared Smith | P12: N/A | Q12: JDE Support Team | R12: 7 | S12: 0 | T12: PROD | U12: PRODUCTION | V12: Close Ticket | W12: {=IF(H12="Request","No SLA for Request", IF(F12="Emergency",B12+(4/24), WORKDAY(B12, _xlfn.IFS(F12="High", 3, F12="Normal", 5, F12="Low", 10))))} -> No SLA for Request | X12: =IF(K12>=W12,"Yes",IF(W12="No SLA for Request","N/A","No")) -> N/A
A13: 111564 | B13: 44160.66 | C13: Login Issue | D13: Aurora Miller | E13: aurora.miller@outlook.com | F13: Emergency | G13: SAP JDE Support Department | H13: Incident / Problem | I13: Web | J13: Closed | K13: 44175.719 | L13: 44161.16 | M13: 0 | N13: 1 | O13: Stellar Murad | P13: N/A | Q13: SAP Support Team | R13: 5 | S13: 1 | T13: PROD | U13: PRODUCTION | V13: New Ticket | W13: {=IF(H13="Request","No SLA for Request", IF(F13="Emergency",B13+(4/24), WORKDAY(B13, _xlfn.IFS(F13="High", 3, F13="Normal", 5, F13="Low", 10))))} -> 44160.827 | X13: =IF(K13>=W13,"Yes",IF(W13="No SLA for Request","N/A","No")) -> Yes
... A20: 111451 | B20: 44013.383 | C20: Laptop Repair | D20: Monique Smiths | E20: msmiths@yahoo.com | F20: Emergency | G20: InterN/Al Technical Department | H20: Incident / Problem | I20: Phone | J20: Closed | K20: 44021.636 | L20: 44014.708 | M20: 0 | N20: 1 | O20: Jared Smith | P20: N/A | Q20: Network Team | R20: 4 | S20: 0 | T20: NON-PROD | U20: DEVELOPMENT | V20: New Ticket | W20: {=IF(H20="Request","No SLA for Request", IF(F20="Emergency",B20+(4/24), WORKDAY(B20, _xlfn.IFS(F20="High", 3, F20="Normal", 5, F20="Low", 10))))} -> 44013.55 | X20: =IF(K20>=W20,"Yes",IF(W20="No SLA for Request","N/A","No")) -> Yes
A21: 111430 | B21: 43984.435 | C21: Sap Not Accessible | D21: Aurora Miller | E21: aurora.miller@outlook.com | F21: Emergency | G21: SAP JDE Support Department | H21: Incident / Problem | I21: Web | J21: Closed | K21: 43998.741 | L21: N/A | M21: 0 | N21: 1 | O21: Jared Smith | P21: N/A | Q21: SAP Support Team | R21: 11 | S21: 2 | T21: PROD | U21: PRODUCTION | V21: Close Ticket | W21: {=IF(H21="Request","No SLA for Request", IF(F21="Emergency",B21+(4/24), WORKDAY(B21, _xlfn.IFS(F21="High", 3, F21="Normal", 5, F21="Low", 10))))} -> 43984.601 | X21: =IF(K21>=W21,"Yes",IF(W21="No SLA for Request","N/A","No")) -> Yes
A22: 111424 | B22: 43978.393 | C22: Sap Production Is Down | D22: Aurora Miller | E22: aurora.miller@outlook.com | F22: Emergency | G22: SAP JDE Support Department | H22: Incident / Problem | I22: Web | J22: Closed | K22: 43992.726 | L22: N/A | M22: 0 | N22: 1 | O22: Jared Smith | P22: N/A | Q22: SAP Support Team | R22: 12 | S22: 20 | T22: PROD | U22: PRODUCTION | V22: New Ticket | W22: {=IF(H22="Request","No SLA for Request", IF(F22="Emergency",B22+(4/24), WORKDAY(B22, _xlfn.IFS(F22="High", 3, F22="Normal", 5, F22="Low", 10))))} -> 43978.56 | X22: =IF(K22>=W22,"Yes",IF(W22="No SLA for Request","N/A","No")) -> Yes
A23: 111416 | B23: 43948.392 | C23: System Downtime | D23: Aurora Miller | E23: aurora.miller@outlook.com | F23: Emergency | G23: SAP JDE Support Department | H23: Incident / Problem | I23: Web | J23: Closed | K23: 43955.717 | L23: N/A | M23: 0 | N23: 1 | O23: Jared Smith | P23: N/A | Q23: SAP Support Team | R23: 5 | S23: 2 | T23: PROD | U23: PRODUCTION | V23: New Ticket | W23: {=IF(H23="Request","No SLA for Request", IF(F23="Emergency",B23+(4/24), WORKDAY(B23, _xlfn.IFS(F23="High", 3, F23="Normal", 5, F23="Low", 10))))} -> 43948.558 | X23: =IF(K23>=W23,"Yes",IF(W23="No SLA for Request","N/A","No")) -> Yes
A24: 111403 | B24: 43913.4 | C24: Prod: IN/Active Phase / Status: No MaN/Ager | D24: Melody Thompson | E24: mthompson@yahoo.com | F24: Emergency | G24: SAP JDE Support Department | H24: Incident / Problem | I24: Web | J24: Closed | K24: 43916.778 | L24: N/A | M24: 0 | N24: 1 | O24: Jared Smith | P24: N/A | Q24: JDE Support Team | R24: 7 | S24: 2 | T24: PROD | U24: DEVELOPMENT | V24: New Ticket | W24: {=IF(H24="Request","No SLA for Request", IF(F24="Emergency",B24+(4/24), WORKDAY(B24, _xlfn.IFS(F24="High", 3, F24="Normal", 5, F24="Low", 10))))} -> 43913.567 | X24: =IF(K24>=W24,"Yes",IF(W24="No SLA for Request","N/A","No")) -> Yes
A25: 111387 | B25: 43874.384 | C25: Prod: Slowdown Of Jde In Production Instance | D25: Melody Thompson | E25: mthompson@yahoo.com | F25: Emergency | G25: SAP JDE Support Department | H25: Incident / Problem | I25: Web | J25: Closed | K25: 43879.585 | L25: N/A | M25: 0 | N25: 1 | O25: Jared Smith | P25: N/A | Q25: JDE Support Team | R25: 10 | S25: 7 | T25: PROD | U25: DEVELOPMENT | V25: New Ticket | W25: {=IF(H25="Request","No SLA for Request", IF(F25="Emergency",B25+(4/24), WORKDAY(B25, _xlfn.IFS(F25="High", 3, F25="Normal", 5, F25="Low", 10))))} -> 43874.551 | X25: =IF(K25>=W25,"Yes",IF(W25="No SLA for Request","N/A","No")) -> Yes
A26: 111384 | B26: 43871.466 | C26: Sql Access MaN/Ager Sql Error | D26: Aurora Miller | E26: aurora.miller@outlook.com | F26: Emergency | G26: SAP JDE Support Department | H26: Incident / Problem | I26: Web | J26: Closed | K26: 43872.656 | L26: N/A | M26: 0 | N26: 1 | O26: Jared Smith | P26: N/A | Q26: AWS Team | R26: 5 | S26: 2 | T26: PROD | U26: PRODUCTION | V26: Close Ticket | W26: {=IF(H26="Request","No SLA for Request", IF(F26="Emergency",B26+(4/24), WORKDAY(B26, _xlfn.IFS(F26="High", 3, F26="Normal", 5, F26="Low", 10))))} -> 43871.633 | X26: =IF(K26>=W26,"Yes",IF(W26="No SLA for Request","N/A","No")) -> Yes
A27: 111366 | B27: 43833.585 | C27: Error On Finish Enrolling | D27: Marvin Peters | E27: mpeters@outlook.com | F27: Emergency | G27: SAP JDE Support Department | H27: Incident / Problem | I27: Web | J27: Closed | K27: 43844.733 | L27: N/A | M27: 0 | N27: 1 | O27: Jared Smith | P27: N/A | Q27: SAP Support Team | R27: 10 | S27: 2 | T27: PROD | U27: DEVELOPMENT | V27: New Ticket | W27: {=IF(H27="Request","No SLA for Request", IF(F27="Emergency",B27+(4/24), WORKDAY(B27, _xlfn.IFS(F27="High", 3, F27="Normal", 5, F27="Low", 10))))} -> 43833.751 | X27: =IF(K27>=W27,"Yes",IF(W27="No SLA for Request","N/A","No")) -> Yes
A28: 111364 | B28: 43833.456 | C28: Slow Loading In Sap | D28: Jasper John | E28: jasper.john@gmail.com | F28: Emergency | G28: SAP JDE Support Department | H28: Incident / Problem | I28: Web | J28: Closed | K28: 43840.749 | L28: N/A | M28: 0 | N28: 1 | O28: Jared Smith | P28: N/A | Q28: SAP Support Team | R28: 11 | S28: 4 | T28: PROD | U28: DEVELOPMENT | V28: New Ticket | W28: {=IF(H28="Request","No SLA for Request", IF(F28="Emergency",B28+(4/24), WORKDAY(B28, _xlfn.IFS(F28="High", 3, F28="Normal", 5, F28="Low", 10))))} -> 43833.623 | X28: =IF(K28>=W28,"Yes",IF(W28="No SLA for Request","N/A","No")) -> Yes
A29: 111357 | B29: 43809.625 | C29: Request For Reconfigure Of Palo Alto | D29: Tomi Yamamoto | E29: tyamamoto@gmail.com | F29: Emergency | G29: InterN/Al Technical Department | H29: Request | I29: Web | J29: Closed | K29: 43817.692 | L29: 43810.125 | M29: 0 | N29: 1 | O29: Stellar Murad | P29: N/A | Q29: Network Team | R29: 4 | S29: 0 | T29: N/A | U29: N/A | V29: New Ticket | W29: {=IF(H29="Request","No SLA for Request", IF(F29="Emergency",B29+(4/24), WORKDAY(B29, _xlfn.IFS(F29="High", 3, F29="Normal", 5, F29="Low", 10))))} -> No SLA for Request | X29: =IF(K29>=W29,"Yes",IF(W29="No SLA for Request","N/A","No")) -> N/A
A30: 111347 | B30: 43791.691 | C30: Sap Production Downtime Issue | D30: John Brown | E30: jbrown@outlook.com | F30: Emergency | G30: SAP JDE Support Department | H30: Incident / Problem | I30: Web | J30: Closed | K30: 43811.472 | L30: 43792.191 | M30: 0 | N30: 1 | O30: Jared Smith | P30: N/A | Q30: SAP Support Team | R30: 6 | S30: 1 | T30: N/A | U30: N/A | V30: New Ticket | W30: {=IF(H30="Request","No SLA for Request", IF(F30="Emergency",B30+(4/24), WORKDAY(B30, _xlfn.IFS(F30="High", 3, F30="Normal", 5, F30="Low", 10))))} -> 43791.858 | X30: =IF(K30>=W30,"Yes",IF(W30="No SLA for Request","N/A","No")) -> Yes
A31: 111331 | B31: 43761.71 | C31: Delete Or Rollback A Payroll Run | D31: Melody Thompson | E31: mthompson@yahoo.com | F31: Emergency | G31: SAP JDE Support Department | H31: Incident / Problem | I31: Web | J31: Closed | K31: 43773.659 | L31: 43763.708 | M31: 0 | N31: 1 | O31: Jared Smith | P31: N/A | Q31: JDE Support Team | R31: 30 | S31: 26 | T31: N/A | U31: N/A | V31: New Ticket | W31: {=IF(H31="Request","No SLA for Request", IF(F31="Emergency",B31+(4/24), WORKDAY(B31, _xlfn.IFS(F31="High", 3, F31="Normal", 5, F31="Low", 10))))} -> 43761.877 | X31: =IF(K31>=W31,"Yes",IF(W31="No SLA for Request","N/A","No")) -> Yes
A32: 111246 | B32: 43647.588 | C32: Batch Process Of Student Groups Not Working. | D32: Jasper John | E32: jasper.john@gmail.com | F32: Emergency | G32: SAP JDE Support Department | H32: Incident / Problem | I32: Web | J32: Closed | K32: 43760.758 | L32: 43648.088 | M32: 0 | N32: 1 | O32: Jared Smith | P32: N/A | Q32: SAP Support Team | R32: 14 | S32: 3 | T32: N/A | U32: N/A | V32: Close Ticket | W32: {=IF(H32="Request","No SLA for Request", IF(F32="Emergency",B32+(4/24), WORKDAY(B32, _xlfn.IFS(F32="High", 3, F32="Normal", 5, F32="Low", 10))))} -> 43647.754 | X32: =IF(K32>=W32,"Yes",IF(W32="No SLA for Request","N/A","No")) -> Yes
A33: 111265 | B33: 43664.585 | C33: Bpm Staging Error | D33: Atom Short | E33: atom.short@gmail.com | F33: Emergency | G33: InterN/Al Technical Department | H33: Incident / Problem | I33: Web | J33: Closed | K33: 43739.447 | L33: 43665.085 | M33: 0 | N33: 1 | O33: Stellar Murad | P33: N/A | Q33: Help Desk Team | R33: 7 | S33: 0 | T33: N/A | U33: N/A | V33: New Ticket | W33: {=IF(H33="Request","No SLA for Request", IF(F33="Emergency",B33+(4/24), WORKDAY(B33, _xlfn.IFS(F33="High", 3, F33="Normal", 5, F33="Low", 10))))} -> 43664.751 | X33: =IF(K33>=W33,"Yes",IF(W33="No SLA for Request","N/A","No")) -> Yes
A34: 111306 | B34: 43729.445 | C34: Palo Alto Device No Lights On Lan Ports | D34: Tomi Yamamoto | E34: tyamamoto@gmail.com | F34: Emergency | G34: InterN/Al Technical Department | H34: Incident / Problem | I34: Web | J34: Closed | K34: 43735.711 | L34: 43729.945 | M34: 0 | N34: 1 | O34: Stellar Murad | P34: N/A | Q34: Network Team | R34: 11 | S34: 2 | T34: N/A | U34: N/A | V34: New Ticket | W34: {=IF(H34="Request","No SLA for Request", IF(F34="Emergency",B34+(4/24), WORKDAY(B34, _xlfn.IFS(F34="High", 3, F34="Normal", 5, F34="Low", 10))))} -> 43729.612 | X34: =IF(K34>=W34,"Yes",IF(W34="No SLA for Request","N/A","No")) -> Yes
A35: 111147 | B35: 43543.409 | C35: Cannot Login In Sap | D35: Aurora Miller | E35: aurora.miller@outlook.com | F35: Emergency | G35: SAP JDE Support Department | H35: Incident / Problem | I35: Web | J35: Closed | K35: 43719.726 | L35: 43543.909 | M35: 0 | N35: 1 | O35: Jared Smith | P35: N/A | Q35: SAP Support Team | R35: 24 | S35: 9 | T35: N/A | U35: N/A | V35: Close Ticket | W35: {=IF(H35="Request","No SLA for Request", IF(F35="Emergency",B35+(4/24), WORKDAY(B35, _xlfn.IFS(F35="High", 3, F35="Normal", 5, F35="Low", 10))))} -> 43543.576 | X35: =IF(K35>=W35,"Yes",IF(W35="No SLA for Request","N/A","No")) -> Yes
A36: 111254 | B36: 43655.358 | C36: Sap Is Not Accessible | D36: Jasper John | E36: jasper.john@gmail.com | F36: Emergency | G36: SAP JDE Support Department | H36: Incident / Problem | I36: Web | J36: Closed | K36: 43719.724 | L36: N/A | M36: 0 | N36: 1 | O36: Jared Smith | P36: N/A | Q36: SAP Support Team | R36: 21 | S36: 6 | T36: N/A | U36: N/A | V36: Close Ticket | W36: {=IF(H36="Request","No SLA for Request", IF(F36="Emergency",B36+(4/24), WORKDAY(B36, _xlfn.IFS(F36="High", 3, F36="Normal", 5, F36="Low", 10))))} -> 43655.525 | X36: =IF(K36>=W36,"Yes",IF(W36="No SLA for Request","N/A","No")) -> Yes
A37: 111283 | B37: 43685.303 | C37: Jde Prod Not Available | D37: Julius Wright | E37: jwirght@outlook.com | F37: Emergency | G37: SAP JDE Support Department | H37: Incident / Problem | I37: Web | J37: Closed | K37: 43705.465 | L37: 43685.803 | M37: 0 | N37: 1 | O37: Jared Smith | P37: N/A | Q37: JDE Support Team | R37: 9 | S37: 1 | T37: N/A | U37: N/A | V37: New Ticket | W37: {=IF(H37="Request","No SLA for Request", IF(F37="Emergency",B37+(4/24), WORKDAY(B37, _xlfn.IFS(F37="High", 3, F37="Normal", 5, F37="Low", 10))))} -> 43685.47 | X37: =IF(K37>=W37,"Yes",IF(W37="No SLA for Request","N/A","No")) -> Yes
A38: 111258 | B38: 43657.338 | C38: Error 504 | D38: Marvin Peters | E38: mpeters@outlook.com | F38: Emergency | G38: SAP JDE Support Department | H38: Incident / Problem | I38: Web | J38: Closed | K38: 43663.742 | L38: 43657.838 | M38: 0 | N38: 1 | O38: Jared Smith | P38: N/A | Q38: SAP Support Team | R38: 10 | S38: 5 | T38: N/A | U38: N/A | V38: Close Ticket | W38: {=IF(H38="Request","No SLA for Request", IF(F38="Emergency",B38+(4/24), WORKDAY(B38, _xlfn.IFS(F38="High", 3, F38="Normal", 5, F38="Low", 10))))} -> 43657.505 | X38: =IF(K38>=W38,"Yes",IF(W38="No SLA for Request","N/A","No")) -> Yes
A39: 111222 | B39: 43620.398 | C39: Create Specific Function In The Responsibility | D39: Wilson Campus | E39: wilson.campus@yahoo.com | F39: Emergency | G39: SAP JDE Support Department | H39: Incident / Problem | I39: Web | J39: Closed | K39: 43630.589 | L39: 43623.708 | M39: 0 | N39: 1 | O39: Jared Smith | P39: N/A | Q39: JDE Support Team | R39: 25 | S39: 8 | T39: N/A | U39: N/A | V39: New Ticket | W39: {=IF(H39="Request","No SLA for Request", IF(F39="Emergency",B39+(4/24), WORKDAY(B39, _xlfn.IFS(F39="High", 3, F39="Normal", 5, F39="Low", 10))))} -> 43620.565 | X39: =IF(K39>=W39,"Yes",IF(W39="No SLA for Request","N/A","No")) -> Yes
A40: 111210 | B40: 43612.449 | C40: Error Loading Position List In Authority To Travel | D40: Paul Jiggins | E40: pjiggins@yahoo.com | F40: Emergency | G40: SAP JDE Support Department | H40: Incident / Problem | I40: Web | J40: Closed | K40: 43630.579 | L40: 43626.708 | M40: 0 | N40: 1 | O40: Jared Smith | P40: N/A | Q40: JDE Support Team | R40: 9 | S40: 5 | T40: N/A | U40: N/A | V40: New Ticket | W40: {=IF(H40="Request","No SLA for Request", IF(F40="Emergency",B40+(4/24), WORKDAY(B40, _xlfn.IFS(F40="High", 3, F40="Normal", 5, F40="Low", 10))))} -> 43612.616 | X40: =IF(K40>=W40,"Yes",IF(W40="No SLA for Request","N/A","No")) -> Yes
A41: 111168 | B41: 43559.667 | C41: Jde Prod Slowdown | D41: Julius Wright | E41: jwirght@outlook.com | F41: Emergency | G41: SAP JDE Support Department | H41: Incident / Problem | I41: Web | J41: Closed | K41: 43630.575 | L41: 43560.167 | M41: 0 | N41: 1 | O41: Jared Smith | P41: N/A | Q41: JDE Support Team | R41: 25 | S41: 5 | T41: N/A | U41: N/A | V41: Close Ticket | W41: {=IF(H41="Request","No SLA for Request", IF(F41="Emergency",B41+(4/24), WORKDAY(B41, _xlfn.IFS(F41="High", 3, F41="Normal", 5, F41="Low", 10))))} -> 43559.833 | X41: =IF(K41>=W41,"Yes",IF(W41="No SLA for Request","N/A","No")) -> Yes
A42: 111225 | B42: 43622.359 | C42: UN/Able To Login In Prod Instance | D42: John Brown | E42: jbrown@outlook.com | F42: Emergency | G42: SAP JDE Support Department | H42: Incident / Problem | I42: Web | J42: Closed | K42: 43629.546 | L42: 43622.859 | M42: 0 | N42: 1 | O42: Jared Smith | P42: N/A | Q42: SAP Support Team | R42: 11 | S42: 1 | T42: N/A | U42: N/A | V42: Close Ticket | W42: {=IF(H42="Request","No SLA for Request", IF(F42="Emergency",B42+(4/24), WORKDAY(B42, _xlfn.IFS(F42="High", 3, F42="Normal", 5, F42="Low", 10))))} -> 43622.526 | X42: =IF(K42>=W42,"Yes",IF(W42="No SLA for Request","N/A","No")) -> Yes
A43: 111219 | B43: 43616.483 | C43: Oracle Hrms - Element Entry Setup | D43: Wilson Campus | E43: wilson.campus@yahoo.com | F43: Emergency | G43: SAP JDE Support Department | H43: Request | I43: Web | J43: Closed | K43: 43626.619 | L43: 43626.708 | M43: 0 | N43: 1 | O43: Jared Smith | P43: N/A | Q43: JDE Support Team | R43: 14 | S43: 6 | T43: N/A | U43: N/A | V43: New Ticket | W43: {=IF(H43="Request","No SLA for Request", IF(F43="Emergency",B43+(4/24), WORKDAY(B43, _xlfn.IFS(F43="High", 3, F43="Normal", 5, F43="Low", 10))))} -> No SLA for Request | X43: =IF(K43>=W43,"Yes",IF(W43="No SLA for Request","N/A","No")) -> N/A
A44: 111188 | B44: 43584.637 | C44: Jde Prod - Error In Workflow Background Process | D44: Julius Wright | E44: jwirght@outlook.com | F44: Emergency | G44: SAP JDE Support Department | H44: Incident / Problem | I44: Web | J44: Closed | K44: 43620.722 | L44: 43585.137 | M44: 0 | N44: 1 | O44: Jared Smith | P44: N/A | Q44: JDE Support Team | R44: 45 | S44: 3 | T44: N/A | U44: N/A | V44: Close Ticket | W44: {=IF(H44="Request","No SLA for Request", IF(F44="Emergency",B44+(4/24), WORKDAY(B44, _xlfn.IFS(F44="High", 3, F44="Normal", 5, F44="Low", 10))))} -> 43584.804 | X44: =IF(K44>=W44,"Yes",IF(W44="No SLA for Request","N/A","No")) -> Yes
A45: 111184 | B45: 43579.596 | C45: Jde Prod - Slowdown Access | D45: Julius Wright | E45: jwirght@outlook.com | F45: Emergency | G45: SAP JDE Support Department | H45: Incident / Problem | I45: Web | J45: Closed | K45: 43599.806 | L45: 43580.096 | M45: 0 | N45: 1 | O45: Jared Smith | P45: N/A | Q45: JDE Support Team | R45: 14 | S45: 1 | T45: N/A | U45: N/A | V45: New Ticket | W45: {=IF(H45="Request","No SLA for Request", IF(F45="Emergency",B45+(4/24), WORKDAY(B45, _xlfn.IFS(F45="High", 3, F45="Normal", 5, F45="Low", 10))))} -> 43579.762 | X45: =IF(K45>=W45,"Yes",IF(W45="No SLA for Request","N/A","No")) -> Yes
A46: 111171 | B46: 43563.369 | C46: Jde Prod Error - Fail Web Server | D46: Julius Wright | E46: jwirght@outlook.com | F46: Emergency | G46: SAP JDE Support Department | H46: Incident / Problem | I46: Web | J46: Closed | K46: 43584.713 | L46: 43563.869 | M46: 0 | N46: 1 | O46: Jared Smith | P46: N/A | Q46: JDE Support Team | R46: 15 | S46: 1 | T46: N/A | U46: N/A | V46: New Ticket | W46: {=IF(H46="Request","No SLA for Request", IF(F46="Emergency",B46+(4/24), WORKDAY(B46, _xlfn.IFS(F46="High", 3, F46="Normal", 5, F46="Low", 10))))} -> 43563.535 | X46: =IF(K46>=W46,"Yes",IF(W46="No SLA for Request","N/A","No")) -> Yes
...

Sheet Pivot Table
A2: Total Tickets per Team
A3: Row Labels | B3: Count of Team Assigned | C3: Count of Team Assigned2
A4: AWS Team | B4: 5 | C4: 0.01607717
A5: BPM - ProcessMaker Support Team | B5: 2 | C5: 0.0064308682 | G5: 42
A6: Help Desk Team | B6: 6 | C6: 0.019292605
A7: JDE Support Team | B7: 170 | C7: 0.54662379
A8: Network Team | B8: 14 | C8: 0.045016077
A9: SAP Support Team | B9: 110 | C9: 0.35369775
A10: Workday Team | B10: 4 | C10: 0.012861736
A11: Grand Total | B11: 311 | C11: 1
S33: Total Tickets per Priority
S34: Row Labels | T34: Count of Priority
S35: Emergency | T35: 50
S36: High | T36: 112
S37: Low | T37: 39
S38: Normal | T38: 335
S39: Grand Total | T39: 536

Sheet Pivot chart
B3: Current Ticket per Status
B5: Row Labels | C5: Count of Ticket per Current Status
B6: Closed | C6: 288
B7: Open | C7: 15
B8: Resolved | C8: 8
B9: Grand Total | C9: 311

Sheet Ticket Viewer
B2: Enter Ticket Number:
B4: Subject | C4: =_xlfn.XLOOKUP(C2, helpdesk_tickets!A2:A537, helpdesk_tickets!C2:C537,"Not Found") -> Not Found
B5: From | C5: =_xlfn.XLOOKUP(C2,helpdesk_tickets!A2:A537, helpdesk_tickets!D2:D537,"Not Found") -> Not Found
B6: Date Created | C6: =_xlfn.XLOOKUP(C2,helpdesk_tickets!A2:A537,helpdesk_tickets!B2:B537,"Not Found") -> Not Found
B7: Priority | C7: =_xlfn.XLOOKUP(C2,helpdesk_tickets!A2:A537,helpdesk_tickets!F2:F537,"Not Found") -> Not Found
B8: Type | C8: =_xlfn.XLOOKUP(C2,helpdesk_tickets!A2:A537,helpdesk_tickets!H2:H537,"Not Found") -> Not Found
B9: Status | C9: =_xlfn.XLOOKUP(C2,helpdesk_tickets!A2:A537,helpdesk_tickets!J2:J537,"Not Found") -> Not Found
B10: SLA Due Date | C10: =_xlfn.XLOOKUP(C2,helpdesk_tickets!A2:A537,helpdesk_tickets!W2:W537,"Not Found") -> Not Found
B11: Breached SLA | C11: =_xlfn.XLOOKUP(C2,helpdesk_tickets!A2:A537,helpdesk_tickets!X2:X537,"Not Found") -> Not Found

Sheet Summary
B2: Team Assigned | C2: Total Tickets per Team | E2: Type | F2: Total Tickets per Type | H2: Priority | I2: Total Tickets per Priority
B3: SAP Support Team | C3: =COUNTIF(helpdesk_tickets!Q:Q, "SAP Support Team") -> 188 | E3: Incident / Problem | F3: =COUNTIF(helpdesk_tickets!H:H, "Incident / Problem") -> 364 | H3: Emergency | I3: =COUNTIF(helpdesk_tickets!F:F, "Emergency") -> 50
B4: JDE Support Team | C4: =COUNTIF(helpdesk_tickets!Q:Q, "JDE Support Team") -> 246 | E4: Request | F4: =COUNTIF(helpdesk_tickets!H:H, "Request") -> 172 | H4: High | I4: =COUNTIF(helpdesk_tickets!F:F, "High") -> 112
B5: Network Team | C5: =COUNTIF(helpdesk_tickets!Q:Q, "Network Team") -> 36 | H5: Normal | I5: =COUNTIF(helpdesk_tickets!F:F, "Normal") -> 335
B6: AWS Team | C6: =COUNTIF(helpdesk_tickets!Q:Q, "AWS Team") -> 16 | H6: Low | I6: =COUNTIF(helpdesk_tickets!F:F, "Low") -> 39
B7: Help Desk Team | C7: =COUNTIF(helpdesk_tickets!Q:Q, "Help Desk Team") -> 35
B8: Hardware Team | C8: =COUNTIF(helpdesk_tickets!Q:Q, "Hardware Team") -> 2
B9: BPM - ProcessMaker Support Team | C9: =COUNTIF(helpdesk_tickets!Q:Q, "BPM - ProcessMaker Support Team") -> 2
B10: Salesforce Team | C10: =COUNTIF(helpdesk_tickets!Q:Q, "Salesforce Team") -> 7
B11: Workday Team | C11: =COUNTIF(helpdesk_tickets!Q:Q, "Workday Team") -> 4
B16: Current Status | C16: Total Current Status Ticket | E16: Current Status/Answered | F16: Total Open/Answered Tickets | H16: Source | I16: Total Tickets from Source
B17: Closed | C17: =COUNTIF(helpdesk_tickets!J:J, "Closed") -> 462 | E17: Open/Answered | F17: =COUNTIFS(helpdesk_tickets!J:J, "Open", helpdesk_tickets!N:N, "1") -> 28 | H17: Web | I17: =COUNTIF(helpdesk_tickets!I:I, "Web") -> 481
B18: Resolved | C18: =COUNTIF(helpdesk_tickets!J:J, "Resolved") -> 13 | H18: Email | I18: =COUNTIF(helpdesk_tickets!I:I, "Email") -> 28
B19: Open | C19: =COUNTIF(helpdesk_tickets!J:J, "Open") -> 61 | H19: Phone | I19: =COUNTIF(helpdesk_tickets!I:I, "Phone") -> 24
